Workbook

Sheet RESUMEN
B2: CORSAGA, S.A. - ROSANTA
B3: Cierre de Inventario
B4: Periodo: Mayo 2026
B5: Fecha de cierre: 31/05/2026
B7: INVENTARIO BARRA | C7: Existencia (Q)
B8: Rones | C8: ='DETALLE BARRA'!C12 -> 1058.25
B9: Whisky / Bourbon | C9: ='DETALLE BARRA'!C31 -> 5967.9
B10: Vodka | C10: ='DETALLE BARRA'!C39 -> 8.5
B11: Gin | C11: ='DETALLE BARRA'!C48 -> 645.65
B12: Tequila / Mezcal | C12: ='DETALLE BARRA'!C62 -> 1034.75
B13: Aperitivos / Digestivos | C13: ='DETALLE BARRA'!C81 -> 1715.97
B14: Vinos facturados | C14: ='DETALLE BARRA'!C98 -> 3817.39
B15: Cervezas y sodas | C15: ='DETALLE BARRA'!C118 -> 1927.35
B16: Subtotal BARRA | C16: =SUM(C8:C15) -> 16175.76
B18: INVENTARIO COCINA | C18: Existencia (Q)
B19: Carnes | C19: ='DETALLE COCINA'!D16 -> 1402.125
B20: Mariscos | C20: ='DETALLE COCINA'!D29 -> 316.125
B21: Aves y Lacteos | C21: ='DETALLE COCINA'!D51 -> 1369.84
B22: Abarrotes | C22: ='DETALLE COCINA'!D86 -> 1294.06
B23: Verduras y Especias | C23: ='DETALLE COCINA'!D164 -> 1080.756
B24: Produccion Rosanta | C24: ='DETALLE COCINA'!D224 -> 1982.5
B25: Doorways-Vijusa (limpieza) | C25: ='DETALLE COCINA'!D245 -> 1091.34
B26: Subtotal COCINA | C26: =SUM(C19:C25) -> 8536.746
B28: GRAN TOTAL INVENTARIO | C28: =C16+C26 -> 24712.506
B31: Elaborado por: _______________________
B33: Revisado por: _______________________

Sheet DETALLE BARRA
A1: DETALLE INVENTARIO BARRA - CIERRE MAYO 2026
A3: RONES
A4: Producto | B4: Precio Unit. (Q) | C4: Valor en existencia (Q)
A5: Zacapa 23 | B5: 300 | C5: 240
A6: Zacapa XO | B6: 987 | C6: 0
A7: Botran 12 | B7: 84 | C7: 92.4
A8: Botran Reserva Blanca | B8: 84 | C8: 54.6
A9: Colonial | B9: 150 | C9: 450
A10: Botran Oro | B10: 75 | C10: 131.25
A11: Quezalteca | B11: 50 | C11: 90
A12: Subtotal Rones | C12: =SUM(C5:C11) -> 1058.25
A14: WHISKY / BOURBON
A15: Producto | B15: Precio Unit. (Q) | C15: Valor en existencia (Q)
A16: Jameson | B16: 188 | C16: 37.6
A17: Old Parr | B17: 321.46 | C17: 16.07
A18: Buchannas 12 | B18: 375 | C18: 300
A19: Buchannas 18 | B19: 907.92 | C19: 907.92
A20: Red Label | B20: 185 | C20: 166.5
A21: Black Label | B21: 318.93 | C21: 574.07
A22: Double Black | B22: 411.32 | C22: 246.79
A23: Glenmorangie Original | B23: 700 | C23: 840
A24: Macallan | B24: 700 | C24: 105
A25: Gold Label | B25: 750 | C25: 1425
A26: Glenliveth | B26: 750 | C26: 600
A27: Akashi | B27: 351 | C27: 245.7
... A30: Wild Turkey 101 | B30: 205 | C30: 256.25
A31: Subtotal Whisky / Bourbon | C31: =SUM(C16:C30) -> 5967.9
A33: VODKA
A34: Producto | B34: Precio Unit. (Q) | C34: Valor en existencia (Q)
A35: Smirnoff | B35: 86 | C35: 0
A36: Grey Goose | B36: 397 | C36: 0
A37: Ciroc | B37: 416.38 | C37: 0
A38: Sky | B38: 85 | C38: 8.5
A39: Subtotal Vodka | C39: =SUM(C35:C38) -> 8.5
A41: GIN
A42: Producto | B42: Precio Unit. (Q) | C42: Valor en existencia (Q)
A43: Puerto de Indias Fresa | B43: 143 | C43: 0
A44: Puerto de Indias Rose | B44: 143 | C44: 0
A45: Hendrix | B45: 372 | C45: 0
A46: Gibson | B46: 91.75 | C46: 165.15
...

Sheet DETALLE COCINA
A1: DETALLE INVENTARIO COCINA - CIERRE MAYO 2026
A3: CARNES
A4: Producto | B4: Existencia | C4: Precio (Q) | D4: Valor (Q)
A5: Lomito | B5: 27 | C5: 58 | D5: 587.25
A6: Lomito hamburguesa | B6: 15 | C6: 58 | D6: 217.5
A7: Lomito carpaccio | B7: 2 | C7: 58 | D7: 116
A8: Brisket | B8: 15 | C8: 33 | D8: 123.75
A9: Puyazo | B9: 0 | C9: 72 | D9: 0
A10: Entrana | B10: 0 | C10: 107.65 | D10: 0
A11: Rib Eye | B11: 0 | C11: 193.83 | D11: 0
A12: Costilla | B12: 0 | C12: 24.19 | D12: 0
A13: Costilla porcion | B13: 13 | C13: 20 | D13: 105.625
A14: Tocino | B14: 1 | C14: 60 | D14: 60
A15: Tablas de jamones | B15: 8 | C15: 24 | D15: 192
A16: Subtotal Carnes | D16: =SUM(D5:D15) -> 1402.125
A18: MARISCOS
A19: Producto | B19: Existencia | C19: Precio (Q) | D19: Valor (Q)
A20: Robalo | B20: 0 | C20: 85 | D20: 0
A21: Dorado | B21: 0 | C21: 65 | D21: 0
A22: Dorado porcion | B22: 12 | C22: 26.5 | D22: 119.25
A23: Pargo | B23: 0 | C23: 58 | D23: 0
A24: Atun | B24: 0 | C24: 85 | D24: 0
A25: Pulpo | B25: 0 | C25: 38 | D25: 0
A26: Pulpo porcion | B26: 10 | C26: 30 | D26: 75
A27: Camaron U10 | B27: 0 | C27: 65 | D27: 0
A28: Camaron porcion | B28: 12 | C28: 32.5 | D28: 121.875
A29: Subtotal Mariscos | D29: =SUM(D20:D28) -> 316.125
A31: AVES Y LACTEOS
A32: Producto | B32: Existencia | C32: Precio (Q) | D32: Valor (Q)
A33: Pechuga de pollo | B33: 0 | C33: 26.186 | D33: 0
A34: Pechuga de pollo porcion | B34: 16 | C34: 17.5 | D34: 105
A35: Huevos | B35: 15 | C35: 1.2 | D35: 18
A36: Camembert | B36: 3 | C36: 49 | D36: 147
A37: Camembert empanizado | B37: 7 | C37: 30 | D37: 105
A38: Camembert tabla | B38: 0 | C38: 12.25 | D38: 0
A39: Mozarella | B39: 2 | C39: 36 | D39: 72
A40: Parmezano | B40: 1.5 | C40: 67 | D40: 100.5
A41: Crema granel | B41: 2 | C41: 43 | D41: 86
A42: Labneh | B42: 3 | C42: 40 | D42: 120
A43: Mantequilla | B43: 5 | C43: 57.75 | D43: 288.75
...
